<html>
<head>
<title>Funzioni di Lippincott</title>
<link href="../css/main.css" rel="stylesheet" type="text/css"></link>
</head>
<body>
<p class="page-path"><a href="../index.html#lippincott">risorse</a> | funzioni 
di lippincott</p>
<h1>Funzioni di Lippincott</h1>
<h2>Introduzione</h2>
<p>LE <em>funzioni di Lippincott</em>, cos&igrave; battezzate da Jon Kalb<a href="#ref-3"><sup>[3]</sup></a>, catturano eccezioni C++ e le convertono in codici d'errore. Trovano uso nell'interfacciamento di codice C e C++, in particolare quando si vuole rendere disponibili in C delle funzionalit&agrave; sviluppate in C++. La conversione &egrave; necessaria in quanto le eccezioni C++ innescano un <em>undefined behaviour</em> quando raggiungono il <em>runtime</em> del C:</p>
<blockquote>&hellip;it's undefined behavior to let a C++ exception propagate through C code&hellip;<a href="#ref-4"><sup>[4]</sup></a></blockquote>
<blockquote>&hellip;make sure you catch all possible exceptions in your C-callable C++ functions&hellip;<a href="#ref-6"><sup>[6]</sup></a></blockquote>
<blockquote>&hellip;the C++ standard is somewhat vague about whether you can expect exceptions to behave properly&hellip;<a href="#ref-7"><sup>[7]</sup></a></blockquote>
<h2>Cattura delle eccezioni alla barriera C/C++</h2>
<p>La modalit&agrave; usuale con cui una funzionalit&agrave; C++ che solleva delle eccezioni viene pubblicata in C &egrave; la seguente:</p>
<pre class="code">
#include &lt;cassert&gt;
#include &lt;stdexcept&gt;

void f(int i) {
  if (i &lt; 0)
    throw std::out_of_range(&quot;negative value&quot;);
  else if (i % 2 == 1)
    throw std::invalid_argument(&quot;odd value&quot;);
  // do something with i...
}

// step 1: explicit capture

enum RESPONSE {
  OK,
  INVALID_ARGUMENT,
  OUT_OF_RANGE,
  UNKNOWN_ERROR,
};

extern &quot;C&quot; RESPONSE f_(int i) {
  try {
    f(i);
    return OK;
  } catch (const std::invalid_argument&amp;) {
    return INVALID_ARGUMENT;
  } catch (const std::out_of_range&amp;) {
    return OUT_OF_RANGE;
  } catch (...) {
    return UNKNOWN_ERROR;
  }
}

int main() {
  assert(f_(42) == OK);
  assert(f_(-1) == OUT_OF_RANGE);
  assert(f_(11) == INVALID_ARGUMENT);

  return 0;
}
</pre>
<p>Se le funzioni da pubblicare sono diverse, ognuna con la sua particolare lista di eccezioni da cattuare, &egrave; facile farsi &ldquo;sfuggire&rdquo; qualche tipo di eccezione, specie se il codice C++ &egrave; soggetto ad aggiornamenti, modifiche o <em>refactoring</em>:</p>
<pre class="code">
// ...

<ins>void g(double a, double b) {
  if (a &gt; b)
    throw std::invalid_argument(&quot;a greater than b&quot;);
  else if (a == 0)
    throw std::domain_error(&quot;a is zero&quot;);
  // do something with a and b...
}</ins>

// ...

enum RESPONSE {
  OK,
  INVALID_ARGUMENT,
  OUT_OF_RANGE,
  <ins>DOMAIN_ERROR,</ins>
  UNKNOWN_ERROR,
};

<ins>extern &quot;C&quot; RESPONSE g_(double a, double b) {
  try {
    g(a, b);
    return OK;
  } catch (const std::invalid_argument&amp;) {
    return INVALID_ARGUMENT;
  } catch (const std::domain_error&amp;) {
    return DOMAIN_ERROR;
  } catch (...) {
    return UNKNOWN_ERROR;
  }
}</ins>

int main() {
  assert(f_(42) == OK);
  assert(f_(-1) == OUT_OF_RANGE);
  assert(f_(11) == INVALID_ARGUMENT);

  <ins>assert(g_(1, 1) == OK);
  assert(g_(2, 1) == INVALID_ARGUMENT);
  assert(g_(0, 1) == DOMAIN_ERROR);</ins>

  return 0;
}
</pre>
<p>Conviene dunque centralizzare il codice di cattura e conversione delle eccezioni. Un modo per farlo &egrave; introducendo delle apposite macro:</p>
<pre class="code">
<ins>// step 2: macro-based capture

#define BEGIN_C_BOUNDARY \
  try {

#define END_C_BOUNDARY \
    return OK; \
  } \
  catch (const std::invalid_argument&amp;) { \
    return INVALID_ARGUMENT; \
  } catch (const std::out_of_range&amp;) { \
    return OUT_OF_RANGE; \
  } catch (const std::domain_error&amp;) { \
    return DOMAIN_ERROR; \
  } catch (...) { \
    return UNKNOWN_ERROR; \
  }</ins>

<ins>extern "C" RESPONSE f_macro(int i) {
BEGIN_C_BOUNDARY
  f(i);
END_C_BOUNDARY
}</ins>

<ins>extern "C" RESPONSE g_macro(double a, double b) {
BEGIN_C_BOUNDARY
  g(a, b);
END_C_BOUNDARY
}</ins>

int main() {
  assert(f_(42)   == OK);
  assert(f_(-1)   == OUT_OF_RANGE);
  assert(f_(11)   == INVALID_ARGUMENT);

  assert(g_(1, 1) == OK);
  assert(g_(2, 1) == INVALID_ARGUMENT);
  assert(g_(0, 1) == DOMAIN_ERROR);

  <ins>assert(f_macro(42)   == OK);
  assert(f_macro(-1)   == OUT_OF_RANGE);
  assert(f_macro(11)   == INVALID_ARGUMENT);</ins>

  <ins>assert(g_macro(1, 1) == OK);
  assert(g_macro(2, 1) == INVALID_ARGUMENT);
  assert(g_macro(0, 1) == DOMAIN_ERROR);</ins>

  return 0;
}
</pre>
<p>Un modo alternativo consiste nello sfruttare una funzione ausiliaria <span class="code">error_code_from_exception</span>, la cosiddetta funzione di Lippincott:</p>
<pre class="code">
<ins>// step 3. function-based capture

RESPONSE error_code_from_exception() noexcept {
  try {
    throw; // re-throw the current exception
  } catch (const std::invalid_argument&amp;) {
    return INVALID_ARGUMENT;
  } catch (const std::out_of_range&amp;) {
    return OUT_OF_RANGE;
  } catch (const std::domain_error&amp;) {
    return DOMAIN_ERROR;
  } catch (...) {
    return UNKNOWN_ERROR;
  }
}</ins>

<ins>extern &quot;C&quot; RESPONSE f_lippincott(int i) {
  try {
    f(i);
    return OK;
  }
  catch (...) {
    return error_code_from_exception();
  }
}</ins>

<ins>extern &quot;C&quot; RESPONSE g_lippincott(double a, double b) {
  try {
    g(a, b);
    return OK;
  }
  catch (...) {
    return error_code_from_exception();
  }
}</ins>

int main() {
  // ...

  <ins>assert(f_lippincott(42) == OK);
  assert(f_lippincott(-1) == OUT_OF_RANGE);
  assert(f_lippincott(11) == INVALID_ARGUMENT);</ins>

  <ins>assert(g_lippincott(1, 1) == OK);
  assert(g_lippincott(2, 1) == INVALID_ARGUMENT);
  assert(g_lippincott(0, 1) == DOMAIN_ERROR);</ins>

  return 0;
}
</pre>
<p><span class="code">error_code_from_exception</span> &egrave; dichiarata <span class="code">noexcept</span> per garantire che nessuna eccezione possa sfuggire alle funzioni <span class="code">*_lippincott</span>. Se un'eccezione dovesse propagarsi al di fuori di <span class="code">error_code_from_exception</span>, per effetto della dichiarazione <span class="code">noexcept</span> il programma terminerebbe immediatamente &mdash; attraverso una chiamata a <span class="code">std::terminate()</span>: in questo modo l'<em>undefined behaviour</em> &egrave; scongiurato.</p>
<p>Poich&eacute; <span class="code">error_code_from_exception</span> forza il risollevamento dell'eccezione corrente, &egrave; necessario che tale eccezione esista; per questo motivo la funzione va richiamata <strong>esclusivamente</strong> all'interno di un blocco <span class="code">catch</span> &mdash; una <span class="code">throw;</span> al di fuori di un blocco <span class="code">catch</span> causa una chiamata immediata a <span class="code">std::terminate()</span>.</p>
<pre class="code">
#include &lt;cassert&gt;
<ins>#include &lt;iostream&gt;</ins>
#include &lt;stdexcept&gt;
// ...

int main() {
  // ...

  std::cout &lt;&lt; &quot;response: &quot; &lt;&lt; error_code_from_exception() &lt;&lt; std::endl; // boom!

  return 0;
}
</pre>
<p>Se si intende usare <span class="code">error_code_from_exception</span> anche in altri ambiti, la si pu&ograve; rendere pi&ugrave; sicura verificando esplicitamente l'esistenza dell'eccezione prima di risollevare l'eccezione:</p>
<pre class="code">
RESPONSE error_code_from_exception() noexcept {
  try {
    <ins>if (std::current_exception())</ins>
      throw; // re-throw the current exception
    <ins>else
      return OK;</ins>
  } catch (const std::invalid_argument&amp;) {
    return INVALID_ARGUMENT;
  } catch (const std::out_of_range&amp;) {
    return OUT_OF_RANGE;
  } catch (const std::domain_error&amp;) {
    return DOMAIN_ERROR;
  } catch (...) {
    return UNKNOWN_ERROR;
  }
}
// ...

/* output:
 *
 * response: 0
 */
</pre>
<h2>Funzioni Lippincott e <em>lambda</em></h2>
<p>In <a href="#ref-5"><sup>[5]</sup></a> viene utilizzata una tecnica piuttosto interessante, che consiste nel passare alla funzione di cattura e conversione delle eccezioni anche il frammento di codice C++, sotto forma di funzione lambda. Il codice di interfacciamento diventa cos&igrave; pi&ugrave; compatto:</p>
<pre class="code">
<ins>template &lt;typename F&gt;
RESPONSE lippincott(F&amp;&amp; f) noexcept {
  try {
    f();
    return OK;
  } catch (...) {
    return error_code_from_exception();
  }
}</ins>

<ins>extern &quot;C&quot; RESPONSE f_lippincott_lambda(int i) {
  return lippincott([&amp;]{
    f(i);
  });
}</ins>

<ins>extern &quot;C&quot; RESPONSE g_lippincott_lambda(double a, double b) {
  return lippincott([&amp;]{
    g(a, b);
  });
}</ins>
// ...

int main() {
  // ...

  <ins>assert(f_lippincott_lambda(42) == OK);
  assert(f_lippincott_lambda(-1) == OUT_OF_RANGE);
  assert(f_lippincott_lambda(11) == INVALID_ARGUMENT);</ins>

  <ins>assert(g_lippincott_lambda(1, 1) == OK);
  assert(g_lippincott_lambda(2, 1) == INVALID_ARGUMENT);
  assert(g_lippincott_lambda(0, 1) == DOMAIN_ERROR);</ins>

  return 0;
}
</pre>
<p>La forma generale della barriera C++/C diventa quindi:</p>
<pre class="code">
extern &quot;C&quot; RESPONSE fun_name(args) {
  return lippincott([&amp;]{
    // c++ code that may throw
  });
}
</pre>
<h3>Zucchero sintattico</h3>
<p>Nel suo intervento dal titolo &ldquo;Error Handling in C++&rdquo; &mdash; successivamente ribattezzato &ldquo;Declarative Control Flow&rdquo; &mdash; all'NDC di Oslo del 2014, Alexandrescu fa uso di un oggetto temporaneo e di una particolare forma dell'<span class="code">operator+</span> per specificare una funzione lambda riducendo al minimo il carico sintattico:</p>
<pre class="code">
// original code
// ...
  return lippincott([&amp;]{
    // c++ code that may throw
  });


// auxiliary object with a custom operator+ that
// takes a callable and wraps it with a `lippincott` call
<ins>struct ErrorCodeFromException {
  template &lt;typename F&gt;
  RESPONSE operator+(F&amp;&amp; f) {
    return lippincott(f);
  }
};</ins>

// modified code that instantiates a temporary ErrorCodeFromException
// and passes the C++ code to wrap through a call to the operator+ method
// ...
  return ErrorCodeFromException() + [&amp;]{
    // c++ code that may throw
  };
</pre>
<p>L'uso dell'<span class="code">operator+</span> (o di un qualunque altro operatore binario) consente di eliminare la coppia di parentesi tonde. L'istanziazione dell'oggetto temporaneo e il preambolo della dichiarazione lambda (e, a seconda dei casi, pure il <span class="code">return</span>) possono a questo punto essere nascosti all'interno di una macro:</p>
<pre class="code">
<ins>#define ERROR_CODE_FROM_EXCEPTION \
  ErrorCodeFromException() + [&amp;]</ins>

// final code
// ...
  return ERROR_CODE_FROM_EXCEPTION {
    // c++ code that may throw
  };
</pre>
<p>Il codice nella sua forma definitiva diventa quindi:</p>
<pre class="code">
// ...

<ins>extern &quot;C&quot; RESPONSE f_lippincott_final(int i) {
  return ERROR_CODE_FROM_EXCEPTION {
    f(i);
  };
}</ins>

<ins>extern &quot;C&quot; RESPONSE g_lippincott_final(double a, double b) {
  return ERROR_CODE_FROM_EXCEPTION {
    g(a, b);
  };
}</ins>

int main() {
  // ...

  <ins>assert(f_lippincott_final(42) == OK);
  assert(f_lippincott_final(-1) == OUT_OF_RANGE);
  assert(f_lippincott_final(11) == INVALID_ARGUMENT);</ins>

  <ins>assert(g_lippincott_final(1, 1) == OK);
  assert(g_lippincott_final(2, 1) == INVALID_ARGUMENT);
  assert(g_lippincott_final(0, 1) == DOMAIN_ERROR);</ins>

  return 0;
}
</pre>
<h2>Sorgenti</h2>
<ul>
<li><span class="code"><a 
href="files/lippincott/lippincott.cpp">lippincott.cpp</a></span></li>
</ul>
<h2>Riferimenti</h2>
<ol>
<a name="ref-1"></a>
<li class="ref">Alexandrescu, A. &ldquo;Error Handling in C++&rdquo;. <em>NDC Oslo 2014</em>. &lt;<a href="http://vimeo.com/97329153">http://vimeo.com/97329153</a>&gt;. Visitato il 26/08/2014.</li>
<a name="ref-2"></a>
<li class="ref">Guillemot, N. &ldquo;C++ Secrets - Using a Lippincott Function for Centralized Exception Handling&rdquo;. &lt;<a href="http://cppsecrets.blogspot.it/2013/12/using-lippincott-function-for.html">http://cppsecrets.blogspot.it/2013/12/using-lippincott-function-for.html</a>&gt;. Visitato il 29/07/2014.</li>
<a name="ref-3"></a>
<li class="ref">Kalb, J. &ldquo;Exception-Safe Coding in C++&rdquo;. &lt;<a href="http://exceptionsafecode.com/">http://exceptionsafecode.com/</a>&gt;, visitato il 29/07/2014.</li>
<a name="ref-4"></a>
<li class="ref">&ldquo;Can C functions marked as <span class="code">extern c</span> throw&rdquo;. <em>StackOverflow</em>. &lt;<a href="http://stackoverflow.com/questions/15845681/can-c-functions-marked-as-extern-c-throw">http://stackoverflow.com/questions/15845681/can-c-functions-marked-as-extern-c-throw</a>&gt;. Visitato il 29/07/2014.</li>
<a name="ref-5"></a>
<li class="ref">&ldquo;Exception Boundaries&rdquo;. <em>MSDN</em>. &lt;<a href="http://blogs.msdn.com/b/vcblog/archive/2014/01/16/exception-boundaries.aspx">http://blogs.msdn.com/b/vcblog/archive/2014/01/16/exception-boundaries.aspx</a>&gt;. Visitato il 29/07/2014.</li>
<a name="ref-6"></a>
<li class="ref">&ldquo;How can I create a C++ function f(int,char,float) that is callable by my C code?&rdquo;. <em>C++ FQA Lite</em>. &lt;<a href="http://yosefk.com/c++fqa/mixing.html#fqa-32.6">http://yosefk.com/c++fqa/mixing.html#fqa-32.6</a>&gt;. Visitato il 29/07/2014.</li>
<a name="ref-7"></a>
<li class="ref">&ldquo;Mixing C and C++ code&rdquo;. <em>oracle.com</em>. &lt;<a href="http://www.oracle.com/technetwork/articles/servers-storage-dev/mixingcandcpluspluscode-305840.html">http://www.oracle.com/technetwork/articles/servers-storage-dev/mixingcandcpluspluscode-305840.html</a>&gt;. Visitato il 29/07/2014.</li>
</ol>
<p class="modification-notice">Pagina modificata il 26/08/2014</p>
</body>
</html>
